Workbook

Sheet FinalMap
A1: Strategy_Name | B1: ID_Code | C1: Asset_Class | D1: PreMerge_BlendID | E1: MS_SAA_Name | F1: MS_PreMergeEnd_Date | G1: Strategy_Type | H1: Proxied | I1: InvestedID | J1: SAAisComposite | K1: MonitoringEndDate | L1: MonitoringStartDate | M1: MS_SAA_Licensed | N1: ExceptionSAA | O1: Currency | P1: Managed_Account_ID | Q1: Alpha_Target | R1: Tracking_Error
A2: 360 One India | B2: LU2444715366 | C2: Equity | D2: MS_RagSAA1 | E2: MSCI India IMI | F2: 45808 | G2: TF | J2: FALSE | Q2: 0.04 | R2: 0.06
A3: AB Global Healthcare | B3: 719168 | C3: Equity | D3: MS_RagSAA3 | E3: MSCI World/Healthcare | F3: 45808 | G3: Del | O3: EUR | P3: MA503 | Q3: 0.025 | R3: 0.04
A4: Acadian European Equity | B4: 708786 | C4: Equity | D4: MS_RagSAA2 | E4: MSCI Europe | F4: 45808 | G4: Del | O4: EUR | P4: MA105 | Q4: 0.02 | R4: 0.04
A5: Advent Global Balanced Convertible | B5: 724767 | C5: Fixed Income | D5: MS_RagSAA116 | E5: Refinitiv Global Focus Hgd CB TR USD | F5: 45808 | G5: Del | L5: 45991 | O5: USD | P5: MA617 | Q5: 0.02 | R5: 0.03
A6: Algebris Financial Income | B6: 657375 | C6: Fixed Income | D6: MS_RagSAA79 | E6: 15% MSCI World Financial Index local currencies (NDWLFNCL Index) perfectly hedged / 25% The BofA Merrill Lynch Contingent Capital Index EUR hedged (COCO Index) / 60%% ICE BofAML Euro Financial Index (EB00) | F6: 45808 | G6: Del | O6: EUR | P6: MA64 | Q6: 0.02 | R6: 0.045
A7: Alliance Bernstein Sustainable Global Thematic | B7: 719169 | C7: Equity | D7: MS_RagSAA4 | E7: MSCI ACWI | F7: 45808 | G7: Del | K7: 45961 | O7: EUR | P7: MA502 | Q7: 0.015 | R7: 0.06
A8: Allianz Germany | B8: LU0840615578 | C8: Equity | D8: MS_RagSAA5 | E8: MSCI Germany IMI | F8: 45808 | G8: TF | J8: FALSE | K8: 45961 | Q8: 0.025 | R8: 0.05
A9: Alma Eikoh Japan | B9: LU1870374508 | C9: Equity | D9: MS_RagSAA6 | E9: MSCI Japan IMI | F9: 45808 | G9: TF | J9: FALSE | Q9: 0.02 | R9: 0.05
A10: AQR EM Enhanced Equity | B10: 597016 | C10: Equity | D10: MS_RagSAA7 | E10: MSCI EM | F10: 45808 | G10: Del | O10: EUR | P10: MA3 | Q10: 0.01 | R10: 0.03
A11: AQR Global Enhanced Equity | B11: 686585 | C11: Equity | D11: MS_RagSAA8 | E11: MSCI World | F11: 45808 | G11: Del | O11: EUR | P11: MA13 | Q11: 0.01 | R11: 0.03
A12: AQR Pacific Equity | B12: 597012 | C12: Equity | D12: MS_RagSAA9 | E12: MSCI AC Asia Pacific | F12: 45808 | G12: Del | O12: EUR | P12: MA19 | Q12: 0.01 | R12: 0.03
A13: AQR US Enhanced Equity | B13: 597009 | C13: Equity | D13: MS_RagSAA10 | E13: MSCI USA | F13: 45808 | G13: Del | O13: EUR | P13: MA17 | Q13: 0.01 | R13: 0.03
A14: ARGA Global Equity | B14: 724627 | C14: Equity | D14: MS_RagSAA114 | E14: MSCI ACWI Enhanced Value | F14: 45808 | G14: Del | L14: 45960 | O14: EUR | P14: MA610 | Q14: 0.02 | R14: 0.06
A15: Artisan EMD Opportunities | B15: IE0007LWGYY1 | C15: Fixed Income | D15: MS_RagSAA78 | E15: 50% ICE BofA US Emerging Markets External Sovereign / 50% ICE BofA Diversified Emerging Markets Sovereign Bond | F15: 45808 | G15: TF | J15: TRUE | M15: FALSE | O15: EUR | Q15: 0.03 | R15: 0.045
A16: Artisan Global Opportunities | B16: IE00B615T757 | C16: Equity | D16: MS_RagSAA11 | E16: MSCI ACWI Growth | F16: 45808 | G16: TF | J16: FALSE | Q16: 0.015 | R16: 0.06
A17: Artisan Global Value | B17: IE00B4M6YD48 | C17: Equity | D17: MS_RagSAA12 | E17: MSCI ACWI Value | F17: 45808 | G17: TF | J17: FALSE | Q17: 0.025 | R17: 0.05
A18: Atlas Global Infrastructure | B18: IE00BKTZQN06 | C18: Equity | D18: MS_RagSAA13 | E18: 50% FTSE Global Core 50/50 / 50% S&P Global Infrastructure | F18: 45808 | G18: TF | J18: TRUE | M18: FALSE | N18: TRUE | Q18: 0.025 | R18: 0.06
A19: Axiom Concentrated Global Growth | B19: 714548 | C19: Equity | D19: MS_RagSAA14 | E19: MSCI ACWI Growth | F19: 45808 | G19: Del | O19: EUR | P19: MA172 | Q19: 0.02 | R19: 0.07
A20: Axiom Emerging Markets Equity | B20: 716407 | C20: Equity | D20: MS_RagSAA15 | E20: MSCI EM Growth | F20: 45808 | G20: Del | O20: EUR | P20: MA482 | Q20: 0.025 | R20: 0.04
A21: Baillie Gifford Positive Change | B21: 701535 | C21: Equity | D21: MS_RagSAA16 | E21: MSCI ACWI Growth | F21: 45808 | G21: Del | O21: EUR | P21: MA68 | Q21: 0.025 | R21: 0.1
A22: Barings Emerging Markets Sovereign | B22: IE00BM99WQ17 | C22: Fixed Income | D22: MS_RagSAA80 | E22: JPM EMBI Global Diversified | F22: 45808 | G22: TF | J22: FALSE | K22: 45808 | O22: EUR | Q22: 0.022 | R22: #N/A
A23: Bin Yuan All China | B23: LU2200556392 | C23: Equity | D23: MS_RagSAA17 | E23: 50% MSCI China All Shares / 50% MSCI China All Shares Quality | F23: 45808 | G23: TF | J23: TRUE | N23: TRUE | Q23: 0.05 | R23: 0.1
A24: BlackRock Circular Economy | B24: LU2041044764 | C24: Equity | D24: MS_RagSAA18 | E24: MSCI World | F24: 45808 | G24: TF | J24: FALSE | K24: 45869 | Q24: 0.015 | R24: #N/A
A25: BlackRock Continental European Flexible | B25: LU1505937943 | C25: Equity | D25: MS_RagSAA19 | E25: MSCI Europe ex UK Growth | F25: 45808 | G25: TF | J25: FALSE | Q25: 0.025 | R25: 0.055
A26: BlackRock World Energy | B26: 724572 | C26: Equity | D26: MS_RagSAA113 | E26: MSCI World Energy 10/40 | F26: 45808 | G26: Del | O26: EUR | P26: MA613 | Q26: 0.015 | R26: 0.06
A27: BlueBay Global IG Credit | B27: GFJQ | C27: Fixed Income | D27: MS_RagSAA81 | E27: ICE BofA Global Corporate Index (G0BC) | F27: 45808 | G27: Del | O27: EUR | P27: MA124 | Q27: 0.008 | R27: 0.02
A28: BlueBay IG Euro Aggregate | B28: LU0549545142 | C28: Fixed Income | D28: MS_RagSAA82 | E28: Bloomberg Euro Aggregate (EUR) | F28: 45808 | G28: TF | J28: FALSE | M28: FALSE | O28: EUR | Q28: 0.015 | R28: 0.022
A29: BlueBay IG Euro Government | B29: 689939 | C29: Fixed Income | D29: MS_RagSAA83 | E29: BlueBay IG Euro Aggregate Treasury (EUR) | F29: 45808 | G29: Del | O29: EUR | P29: MA6 | Q29: 0.015 | R29: 0.018
A30: BlueBox Global Technology | B30: 722285 | C30: Equity | D30: MS_RagSAA111 | E30: BlueBox Technology - SAA | F30: 45808 | G30: Del | O30: EUR | P30: MA614 | Q30: 0.015 | R30: 0.06
A31: Brigade US High Yield | B31: 692350 | C31: Fixed Income | D31: MS_RagSAA84 | E31: ICE US High Yield (JUC0) - USD | F31: 45808 | G31: Del | O31: USD | P31: MA29 | Q31: 0.01 | R31: 0.03
A32: Capital Four EUR High Yield | B32: GFJY | C32: Fixed Income | D32: MS_RagSAA85 | E32: C4 Composite: ICE European Currency High Yield, then 31/03/2022 65% HPC0 / 34% JUC0 | F32: 45808 | G32: Del | O32: EUR | P32: MA125 | Q32: 0.0075 | R32: 0.02
A33: Deutsche EHY | B33: 681724 | C33: Fixed Income | D33: MS_RagSAA86 | E33: ICE European Currency High Yield Constrained (HPC0, EUR Unhedged) | F33: 45808 | G33: Del | O33: USD | P33: MA36 | Q33: 0.005 | R33: 0.01
A34: DJE GAMAX Junior | B34: 642651 | C34: Equity | D34: MS_RagSAA20 | E34: DJE GAMAX Junior SAA | F34: 45808 | G34: Del | O34: EUR | P34: MA50 | Q34: 0.02 | R34: 0.05
A35: DWS German Equity | B35: 596990 | C35: Equity | D35: MS_RagSAA21 | E35: 85% MSCI Germany / 15% MSCI Germany Small Cap | F35: 45808 | G35: Del | O35: EUR | P35: MA10 | Q35: 0.005 | R35: 0.02
A36: Eagle Capital US Equity Value | B36: 712560 | C36: Equity | D36: MS_RagSAA22 | E36: MSCI USA | F36: 45808 | G36: Del | O36: USD | P36: MA120 | Q36: 0.02 | R36: 0.05
A37: Eleva Euroland | B37: LU1616921232 | C37: Equity | D37: MS_RagSAA23 | E37: MSCI EMU | F37: 45808 | G37: TF | H37: TRUE | I37: LU1920212195 | J37: FALSE | Q37: 0.02 | R37: #N/A
A38: Eleva European Select Equity Large-Cap | B38: 711342 | C38: Equity | D38: MS_RagSAA24 | E38: MSCI Europe Large Cap | F38: 45808 | G38: Del | K38: 45838 | O38: EUR | P38: MA117 | Q38: 0.02 | R38: 0.04
A39: Eleva European Selection | B39: LU1920210579 | C39: Equity | D39: MS_RagSAA25 | E39: MSCI Europe | F39: 45808 | G39: TF | J39: FALSE | Q39: 0.02 | R39: 0.04
A40: Eleva SMID Equity | B40: LU1920216006 | C40: Equity | D40: MS_RagSAA26 | E40: MSCI Europe Small Cap | F40: 45808 | G40: TF | H40: TRUE | I40: LU1920214647 | J40: FALSE | Q40: 0.02 | R40: #N/A
...

Sheet TE_AT_112025
A1: DelCodeISIN | B1: Strategy Name | C1: Asset Manager | D1: Analyst Estimate - Excess Return | E1: Analyst Estimate - Tracking Error
A2: 169963 | B2: Sector Gamma Health Care | C2: Sector Gamma | D2: 2.5 | E2: 5
A3: 170032 | B3: Arga Global Value | C3: Arga | D3: 2 | E3: 6
A4: 170730 | B4: Impax Environmental Leaders | C4: Impax | D4: 1.5 | E4: 5
A5: 170733 | B5: Impax Nutrition | C5: Impax | D5: 1.5 | E5: 5
A6: 596990 | B6: DWS German Equity | C6: DWS | D6: 0.5 | E6: 2
A7: 596994 | B7: Trea Spain Equity | C7: Trea | D7: 0 | E7: 2
A8: 596998 | B8: Wellington Global Research Equity | C8: Wellington | D8: 1 | E8: 3
A9: 597009 | B9: AQR North America Equity | C9: AQR | D9: 1 | E9: 3
A10: 597012 | B10: AQR Pacific Equity | C10: AQR | D10: 1 | E10: 3
A11: 597016 | B11: AQR Emerging Markets Equity | C11: AQR | D11: 1 | E11: 3
A12: 642651 | B12: DJE Gamax Junior | C12: DJE | D12: 2 | E12: 5
A13: 645766 | B13: Tenax Financial Equity | C13: Tenax | D13: 1.5 | E13: 4.5
... A116: 729695 | B116: KAR International Small Cap Quality | C116: Kayne Anderson Rudnick | D116: 3 | E116: 7
A117: GFJ8 | B117: Muzinich Euro High Yield | C117: Muzinich | D117: 0.8 | E117: 2
A118: GFJ9 | B118: Man GLG European High Yield Opportunities | C118: Man Group | D118: 1.25 | E118: 3.5
A119: GFJQ | B119: BlueBay Global IG Credit (GMB) | C119: BlueBay | D119: 0.8 | E119: 2
A120: GFJR | B120: Deutsche Invest European High Yield | C120: DWS | D120: 0.5 | E120: 1
A121: GFJS | B121: Deutsche Invest European High Yield | C121: DWS | D121: 0.5 | E121: 1
A122: GFJU | B122: Brigade High Yield (GMB) | C122: Brigade | D122: 1 | E122: 3
A123: GFJW | B123: Neuberger Berman Emerging Market 50/50 Blend (GMB) | C123: Neuberger Berman | D123: 1.5 | E123: 3.5
A124: GFJX | B124: PGIM Emerging Market Blend (GMB) | C124: PGIM | D124: 1.1 | E124: 3
A125: GFJY | B125: Capital Four EUR High Yield | C125: Capital Four | D125: 0.75 | E125: 2
A126: Robeco1_6124 | B126: Robeco Global Equity (Compromiso) | C126: Robeco | D126: 0.5 | E126: 3
A127: IE0000AQF1T2 | B127: Acadian Europe | C127: Acadian | D127: 2 | E127: 4
A128: IE0000AQF1T2 | B128: Acadian Europe | C128: Acadian | D128: 2 | E128: 4
... A215: LU2990521093 | B215: Mirabaud Sustainable Convertibles Global | C215: Mirabaud | D215: 1.2 | E215: 4

Sheet Sheet3
A1: TARGET_FUND_ID | B1: TARGET_FUND_INSTRUMENT_ID | C1: MANAGER_ORGANISATION_ID | D1: TARGET_FUND_NAME | E1: ISIN_INSTRUMENT_REFERENCE | F1: BLOOMBERG_INSTRUMENT_REFERENCE | G1: HEDGED_INDICATOR | H1: CURRENCY_ID | I1: CREATED_DATETIME | J1: UPDATED_DATETIME | K1: CREATED_BY_USER | L1: UPDATED_BY_USER
A2: 6 | B2: 5356 | C2: 4 | D2: BGF-CONT EUR FLX-I4 EUR | E2: LU1505937943 | F2: BBG00F0FKNN4 | G2: N | H2: 1 | I2: 45853.502 | J2: 45853.502 | K2: Unknown | L2: Unknown
A3: 8 | B3: 5626 | C3: 34 | D3: BLUEBAY INV GR EU AG B-Q EUR | E3: LU1170327289 | F3: BBG00CGLS776 | G3: N | H3: 1 | I3: 45853.502 | J3: 45853.502 | K3: Unknown | L3: Unknown
A4: 9 | B4: 3188 | C4: 0 | D4: ALLIANZ THEMATICA-WT EUR A | E4: LU2106854214 | F4: BBG00RKBXW06 | G4: N | H4: 1 | I4: 45853.502 | J4: 45853.502 | K4: Unknown | L4: Unknown
A5: 10 | B5: 7014 | C5: 26 | D5: MRG ST IF-SH MAT EU BD-ZE | E5: LU0360478795 | F5: BBG000C4LYZ1 | G5: N | H5: 1 | I5: 45853.502 | J5: 45853.502 | K5: Unknown | L5: Unknown
A6: 12 | B6: 2011 | C6: 0 | D6: MU-GL TAC CR-H EUR ACC G2 UN | E6: IE00BKSKL532 | F6: BBG00RMFXX49 | G6: N | H6: 1 | I6: 45853.502 | J6: 45853.502 | K6: Unknown | L6: Unknown
A7: 15 | B7: 6762 | C7: 94 | D7: DWS- INVEST- EU H YL CP-RDQ | E7: LU1808738642 | F7: BBG00L4K30S0 | G7: N | H7: 1 | I7: 45853.502 | J7: 45853.502 | K7: Unknown | L7: Unknown
A8: 17 | B8: 6882 | C8: 111 | D8: AB SICAV I-INTL HLT CR-S1EPC | E8: LU0260062871 | F8: BBG00PZZQKQ7 | G8: N | H8: 1 | I8: 45853.502 | J8: 45853.502 | K8: Unknown | L8: Unknown
A9: 18 | B9: 5938 | C9: 26 | D9: MSIF-GLOBAL OPPORT-ZH1 EUR | E9: LU2646745732 | F9: BBG01HCV83F8 | G9: N | H9: 1 | I9: 45853.502 | J9: 45853.502 | K9: Unknown | L9: Unknown
A10: 19 | B10: 4992 | C10: 50 | D10: JUPITER JGF DY B FD-I EUR A | E10: LU0853555893 | F10: BBG003NXFNJ8 | G10: N | H10: 1 | I10: 45853.502 | J10: 45853.502 | K10: Unknown | L10: Unknown
A11: 20 | B11: 3571 | C11: 24 | D11: PGIM E/M HRD CUR DB-IDIS | E11: IE000VNQZC87 | F11: BBG013V235H0 | G11: N | H11: 1 | I11: 45853.502 | J11: 45853.502 | K11: Unknown | L11: Unknown
A12: 21 | B12: 1625 | C12: 34 | D12: BLUEBAY INV GR EUR AGG BD-I | E12: LU0549545142 | F12: BBG0018YWBM0 | G12: N | H12: 1 | I12: 45853.502 | J12: 45853.502 | K12: Unknown | L12: Unknown
A13: 23 | B13: 6196 | C13: 36 | D13: CARMIGNAC EMERGENTS-A EUR AC | E13: FR0010149302 | F13: BBG000C0P7T1 | G13: N | H13: 1 | I13: 45853.502 | J13: 45853.502 | K13: Unknown | L13: Unknown
... A165: 164 | B165: 15070695 | C165: 39 | D165: SCHR ISF-GBL SST VAL-IZUSDAC | E165: LU2405386017 | F165: EQ0000000090199151 | G165: N | H165: 153 | I165: 45853.502 | J165: 45853.502 | K165: Unknown | L165: Unknown

Sheet IAvMS_MAP
A1: ID_Code | B1: SophisID | C1: Name | D1: DBCode | E1: FundName | F1: AssetClass | G1: Region | H1: Style | I1: StartDate | J1: EndDate | K1: IsRepresentative | L1: BaseCCY | M1: MsMap | N1: MsStratName | O1: IsUsedforMsRAG | P1: Type | Q1: MappedToType | R1: Note
A2: 708786 | B2: 2422 | C2: Acadian | D2: DB8813 | E2: CH EUROPEAN EQUITY | F2: Equity | G2: Europe | H2: Blend | I2: 44508 | J2: NULL | K2: 1 | L2: EUR | M2: 708786 | N2: Acadian European Equity | O2: TRUE | P2: =IF(LEN(A2)>8,"TF","Del") -> Del | Q2: =IF(LEN(M2)>8,"TF","Del") -> Del
A3: 724767 | B3: 4121 | C3: Advent | D3: DB2016 | E3: MBB CONVERTIBLE STRATEGY COLLECTION | F3: Hybrid | G3: Global | H3: Blend | I3: 45630 | J3: NULL | K3: 1 | L3: USD | M3: 724767 | N3: Advent Global Balanced Convertible | O3: TRUE | P3: =IF(LEN(A3)>8,"TF","Del") -> Del | Q3: =IF(LEN(M3)>8,"TF","Del") -> Del
A4: 657375 | B4: 922 | C4: Algebris | D4: DB6214 | E4: MBB FINANCIAL INCOME STRATEGY | F4: MultiAsset | G4: Global | H4: Income | I4: 42086 | J4: NULL | K4: 1 | L4: EUR | M4: 657375 | N4: Algebris Financial Income | O4: TRUE | P4: =IF(LEN(A4)>8,"TF","Del") -> Del | Q4: =IF(LEN(M4)>8,"TF","Del") -> Del
A5: 719168 | B5: 3782 | C5: AllianceBernstein | D5: DB3784 | E5: CH HEALTHCARE EQUITY EVO. | F5: Equity | G5: Global | H5: Sec_Healthcare | I5: 45257 | J5: NULL | K5: 1 | L5: EUR | M5: 719168 | N5: AB Global Healthcare | O5: TRUE | P5: =IF(LEN(A5)>8,"TF","Del") -> Del | Q5: =IF(LEN(M5)>8,"TF","Del") -> Del
A6: 719169 | B6: 3781 | C6: AllianceBernstein | D6: DB6459 | E6: MBB INNOVATIVE THEMATIC OPPORTUNITIES | F6: Equity | G6: Global | H6: Quality | I6: 45257 | J6: NULL | K6: 1 | L6: EUR | M6: 719169 | N6: Alliance Bernstein Sustainable Global Thematic | O6: TRUE | P6: =IF(LEN(A6)>8,"TF","Del") -> Del | Q6: =IF(LEN(M6)>8,"TF","Del") -> Del
A7: 597012 | B7: 1261 | C7: AQR | D7: DB8814 | E7: CH PACIFIC EQUITY | F7: Equity | G7: APAC | H7: Value | I7: 43297 | J7: NULL | K7: 1 | L7: EUR | M7: 597012 | N7: AQR Pacific Equity | O7: TRUE | P7: =IF(LEN(A7)>8,"TF","Del") -> Del | Q7: =IF(LEN(M7)>8,"TF","Del") -> Del
A8: 597016 | B8: 1201 | C8: AQR | D8: DB8816 | E8: CH EMERGING MARKETS EQUITY | F8: Equity | G8: EM | H8: Value | I8: 43283 | J8: NULL | K8: 1 | L8: EUR | M8: 597016 | N8: AQR EM Enhanced Equity | O8: TRUE | P8: =IF(LEN(A8)>8,"TF","Del") -> Del | Q8: =IF(LEN(M8)>8,"TF","Del") -> Del
A9: 707793 | B9: 2381 | C9: AQR | D9: DB8824 | E9: CH PROVIDENT 1 | F9: Equity | G9: Global | H9: Value | I9: 44424 | J9: NULL | K9: 1 | L9: EUR | M9: 686585 | N9: AQR Global Enhanced Equity | O9: FALSE | P9: =IF(LEN(A9)>8,"TF","Del") -> Del | Q9: =IF(LEN(M9)>8,"TF","Del") -> Del
A10: 727783 | B10: 4281 | C10: AQR | D10: DB5555 | E10: MBB SOCIALLY RESPONSIBLE COLLECTION | F10: Equity | G10: Global | H10: Blend | I10: 45775 | J10: NULL | K10: 0 | L10: EUR | M10: 686585 | N10: AQR Global Enhanced Equity | O10: FALSE | P10: =IF(LEN(A10)>8,"TF","Del") -> Del | Q10: =IF(LEN(M10)>8,"TF","Del") -> Del
A11: 686585 | B11: 1202 | C11: AQR | D11: DB4223 | E11: CH INTERNATIONAL EQUITY | F11: Equity | G11: Global | H11: Blend | I11: 43283 | J11: NULL | K11: 1 | L11: EUR | M11: 686585 | N11: AQR Global Enhanced Equity | O11: TRUE | P11: =IF(LEN(A11)>8,"TF","Del") -> Del | Q11: =IF(LEN(M11)>8,"TF","Del") -> Del
A12: 597009 | B12: 1203 | C12: AQR | D12: DB8812 | E12: CH NORTH AMERICAN EQUITY | F12: Equity | G12: US | H12: Value | I12: 43283 | J12: NULL | K12: 1 | L12: EUR | M12: 597009 | N12: AQR US Enhanced Equity | O12: TRUE | P12: =IF(LEN(A12)>8,"TF","Del") -> Del | Q12: =IF(LEN(M12)>8,"TF","Del") -> Del
A13: 727790 | B13: 4261 | C13: Arga | D13: DB4211 | E13: MBB EQUITY POWER COUPON COLLECTION | F13: Equity | G13: Global | H13: Value | I13: 45770 | J13: NULL | K13: 1 | L13: EUR | M13: 724627 | N13: ARGA Global Equity | O13: FALSE | P13: =IF(LEN(A13)>8,"TF","Del") -> Del | Q13: =IF(LEN(M13)>8,"TF","Del") -> Del
... A26: 689939 | B26: 1365 | C26: Bluebay | D26: DB8818 | E26: CH EURO BOND | F26: FixedIncome | G26: Europe | H26: Government | I26: 43410 | J26: NULL | K26: 1 | L26: EUR | M26: 689939 | N26: BlueBay IG Euro Government | O26: TRUE | P26: =IF(LEN(A26)>8,"TF","Del") -> Del | Q26: =IF(LEN(M26)>8,"TF","Del") -> Del
A27: GFJQ | B27: 2566 | C27: Bluebay | D27: CHIN | E27: MGF GLOBALE MULTI BOND | F27: FixedIncome | G27: Global | H27: Aggregate | I27: 44599 | J27: NULL | K27: 1 | L27: EUR | M27: GFJQ | N27: BlueBay Global IG Credit | O27: TRUE | P27: =IF(LEN(A27)>8,"TF","Del") -> Del | Q27: =IF(LEN(M27)>8,"TF","Del") -> Del
A28: 722285 | B28: 4101 | C28: BlueBox | D28: DB3785 | E28: CH TECHNOLOGY EQUITY EVO. | F28: Equity | G28: Global | H28: Sec_Tech | I28: 45618 | J28: NULL | K28: 1 | L28: EUR | M28: 722285 | N28: BlueBox Global Technology | O28: TRUE | P28: =IF(LEN(A28)>8,"TF","Del") -> Del | Q28: =IF(LEN(M28)>8,"TF","Del") -> Del
A29: GFJU | B29: 2570 | C29: Brigade | D29: CHIN | E29: MGF GLOBALE MULTI BOND | F29: FixedIncome | G29: US | H29: HighYield | I29: 44599 | J29: NULL | K29: 0 | L29: EUR | M29: 692350 | N29: Brigade US High Yield | O29: FALSE | P29: =IF(LEN(A29)>8,"TF","Del") -> Del | Q29: =IF(LEN(M29)>8,"TF","Del") -> Del
A30: 692350 | B30: 1441 | C30: Brigade | D30: DB3015 | E30: MBB GLOBAL HIGH YIELD | F30: FixedIncome | G30: US | H30: HighYield | I30: 43586 | J30: NULL | K30: 1 | L30: USD | M30: 692350 | N30: Brigade US High Yield | O30: TRUE | P30: =IF(LEN(A30)>8,"TF","Del") -> Del | Q30: =IF(LEN(M30)>8,"TF","Del") -> Del
A31: GFJY | B31: 2572 | C31: Capital Four | D31: CREA | E31: MGF EURO HIGH YIELD | F31: FixedIncome | G31: Europe | H31: HighYield | I31: 44599 | J31: NULL | K31: 1 | L31: EUR | M31: GFJY | N31: Capital Four EUR High Yield | O31: TRUE | P31: =IF(LEN(A31)>8,"TF","Del") -> Del | Q31: =IF(LEN(M31)>8,"TF","Del") -> Del
A32: 642651 | B32: 961 | C32: DJE | D32: LU4136 | E32: GAMAX FUNDS JUNIOR | F32: Equity | G32: Global | H32: Sec_Consumer | I32: 41302 | J32: NULL | K32: 1 | L32: EUR | M32: 642651 | N32: DJE GAMAX Junior | O32: TRUE | P32: =IF(LEN(A32)>8,"TF","Del") -> Del | Q32: =IF(LEN(M32)>8,"TF","Del") -> Del
A33: 596990 | B33: 1062 | C33: DWS | D33: DB3896 | E33: CH GERMANY EQUITY | F33: Equity | G33: Germany | H33: Blend | I33: 42919 | J33: NULL | K33: 1 | L33: EUR | M33: 596990 | N33: DWS German Equity | O33: TRUE | P33: =IF(LEN(A33)>8,"TF","Del") -> Del | Q33: =IF(LEN(M33)>8,"TF","Del") -> Del
A34: GFJR | B34: 2565 | C34: DWS | D34: CHIN | E34: MGF GLOBALE MULTI BOND | F34: FixedIncome | G34: Europe | H34: HighYield | I34: 44599 | J34: NULL | K34: 0 | L34: EUR | M34: 681724 | N34: Deutsche EHY | O34: FALSE | P34: =IF(LEN(A34)>8,"TF","Del") -> Del | Q34: =IF(LEN(M34)>8,"TF","Del") -> Del
A35: GFJS | B35: 2574 | C35: DWS | D35: CREA | E35: MGF EURO HIGH YIELD | F35: FixedIncome | G35: Europe | H35: HighYield | I35: 44599 | J35: NULL | K35: 0 | L35: EUR | M35: 681724 | N35: Deutsche EHY | O35: FALSE | P35: =IF(LEN(A35)>8,"TF","Del") -> Del | Q35: =IF(LEN(M35)>8,"TF","Del") -> Del
A36: 681724 | B36: 1101 | C36: DWS | D36: DB3015 | E36: MBB GLOBAL HIGH YIELD | F36: FixedIncome | G36: Europe | H36: HighYield | I36: 43061 | J36: NULL | K36: 1 | L36: EUR | M36: 681724 | N36: Deutsche EHY | O36: TRUE | P36: =IF(LEN(A36)>8,"TF","Del") -> Del | Q36: =IF(LEN(M36)>8,"TF","Del") -> Del
A37: 712560 | B37: 2741 | C37: Eagle | D37: DB8812 | E37: CH NORTH AMERICAN EQUITY | F37: Equity | G37: US | H37: Blend | I37: 44706 | J37: NULL | K37: 1 | L37: USD | M37: 712560 | N37: Eagle Capital US Equity Value | O37: TRUE | P37: =IF(LEN(A37)>8,"TF","Del") -> Del | Q37: =IF(LEN(M37)>8,"TF","Del") -> Del
A38: 711342 | B38: 2681 | C38: Eleva | D38: DB8813 | E38: CH EUROPEAN EQUITY | F38: Equity | G38: Europe | H38: Blend | I38: 44691 | J38: NULL | K38: 1 | L38: EUR | M38: 711342 | N38: Eleva European Select Equity Large-Cap | O38: TRUE | P38: =IF(LEN(A38)>8,"TF","Del") -> Del | Q38: =IF(LEN(M38)>8,"TF","Del") -> Del
A39: 729235 | B39: 4381 | C39: Evolutionary Tree | D39: DB6459 | E39: MBB INNOVATIVE THEMATIC OPPORTUNITIES | F39: Equity | G39: Global | H39: Growth | I39: 45813 | J39: NULL | K39: 1 | L39: EUR | O39: FALSE | P39: =IF(LEN(A39)>8,"TF","Del") -> Del | Q39: =IF(LEN(M39)>8,"TF","Del") -> Del
A40: 718928 | B40: 3741 | C40: Fidelity | D40: DB3789 | E40: CH INDUSTRIALS AND MATERIALS EQUITY EVO. | F40: Equity | G40: Global | H40: Sec_IndMat | I40: 45240 | J40: NULL | K40: 1 | L40: EUR | M40: 718928 | N40: Fidelity Global Industrials/Materials | O40: TRUE | P40: =IF(LEN(A40)>8,"TF","Del") -> Del | Q40: =IF(LEN(M40)>8,"TF","Del") -> Del
A41: 714703 | B41: 3102 | C41: Fidelity | D41: DB6484 | E41: MBB GLOBAL DEMOGRAPHIC OPPORTUNITIES | F41: Equity | G41: Global | H41: Quality | I41: 44897 | J41: NULL | K41: 1 | L41: EUR | M41: 714703 | N41: Fidelity Global Demographics | O41: TRUE | P41: =IF(LEN(A41)>8,"TF","Del") -> Del | Q41: =IF(LEN(M41)>8,"TF","Del") -> Del
A42: 707638 | B42: 2321 | C42: Fidelity | D42: LU4136 | E42: GAMAX FUNDS JUNIOR | F42: Equity | G42: Sec_Consumer | H42: Quality | I42: 44403 | J42: NULL | K42: 1 | L42: EUR | M42: 707638 | N42: Fidelity Global Consumer | O42: TRUE | P42: =IF(LEN(A42)>8,"TF","Del") -> Del | Q42: =IF(LEN(M42)>8,"TF","Del") -> Del
A43: 722394 | B43: 3922 | C43: FirstSentier | D43: DB6510 | E43: MBB GLOBAL IMPACT | F43: Equity | G43: Global | H43: Quality | I43: 45456 | J43: NULL | K43: 1 | L43: EUR | M43: 722394 | N43: Stewart Worldwide Sustainability | O43: TRUE | P43: =IF(LEN(A43)>8,"TF","Del") -> Del | Q43: =IF(LEN(M43)>8,"TF","Del") -> Del
A44: 716405 | B44: 3341 | C44: FountainCap | D44: DB6501 | E44: MBB CHINESE ROAD OPPORTUNITIES | F44: Equity | G44: China | H44: Quality | I44: 45037 | J44: NULL | K44: 1 | L44: EUR | M44: 716405 | N44: FountainCap China Opportunity | O44: TRUE | P44: =IF(LEN(A44)>8,"TF","Del") -> Del | Q44: =IF(LEN(M44)>8,"TF","Del") -> Del
A45: 708787 | B45: 2501 | C45: Goldman Sachs | D45: DB6501 | E45: MBB CHINESE ROAD OPPORTUNITIES | F45: Equity | G45: China | H45: Blend | I45: 44533 | J45: NULL | K45: 1 | L45: EUR | M45: 708787 | N45: GS All China Equity | O45: TRUE | P45: =IF(LEN(A45)>8,"TF","Del") -> Del | Q45: =IF(LEN(M45)>8,"TF","Del") -> Del
A46: 714113 | B46: 3022 | C46: Goldman Sachs | D46: DB6575 | E46: MBB INDIA OPPORTUNITIES | F46: Equity | G46: EM | H46: Blend | I46: 45065 | J46: NULL | K46: 1 | L46: EUR | M46: 714113 | N46: GS India | O46: TRUE | P46: =IF(LEN(A46)>8,"TF","Del") -> Del | Q46: =IF(LEN(M46)>8,"TF","Del") -> Del
A47: 716542 | B47: 3461 | C47: GuardCap | D47: DB6592 | E47: MBB GLOBAL EQUITY STYLE SELECTION | F47: Equity | G47: Global | H47: Quality | I47: 45065 | J47: NULL | K47: 1 | L47: USD | M47: 716542 | N47: GuardCap Global Equity | O47: TRUE | P47: =IF(LEN(A47)>8,"TF","Del") -> Del | Q47: =IF(LEN(M47)>8,"TF","Del") -> Del
A48: 716541 | B48: 3501 | C48: GuardCap | D48: DB6502 | E48: MBB GLOBAL LEADERS | F48: Equity | G48: Global | H48: Quality | I48: 45072 | J48: NULL | K48: 0 | L48: USD | M48: 716542 | N48: GuardCap Global Equity | O48: FALSE | P48: =IF(LEN(A48)>8,"TF","Del") -> Del | Q48: =IF(LEN(M48)>8,"TF","Del") -> Del
A49: 718556 | B49: 3721 | C49: Impax | D49: DB6510 | E49: MBB GLOBAL IMPACT | F49: Equity | G49: Global | H49: Blend | I49: 45233 | J49: NULL | K49: 1 | L49: EUR | M49: 718556 | N49: Impax Environmental Leaders | O49: TRUE | P49: =IF(LEN(A49)>8,"TF","Del") -> Del | Q49: =IF(LEN(M49)>8,"TF","Del") -> Del
A50: 716676 | B50: 3621 | C50: JPMorgan | D50: LU4133 | E50: GAMAX FUNDS ASIA PACIFIC | F50: Equity | G50: APAC | H50: Growth | I50: 45191 | J50: NULL | K50: 0 | L50: EUR | M50: 682593 | N50: JPM Pacific Equity | O50: FALSE | P50: =IF(LEN(A50)>8,"TF","Del") -> Del | Q50: =IF(LEN(M50)>8,"TF","Del") -> Del
A51: 682593 | B51: 1127 | C51: JPMorgan | D51: DB3017 | E51: MBB PACIFIC COLLECTION | F51: Equity | G51: APAC | H51: Growth | I51: 43088 | J51: NULL | K51: 1 | L51: EUR | M51: 682593 | N51: JPM Pacific Equity | O51: TRUE | P51: =IF(LEN(A51)>8,"TF","Del") -> Del | Q51: =IF(LEN(M51)>8,"TF","Del") -> Del
... A60: 717479 | B60: 3561 | C60: Lansdowne | D60: DB3018 | E60: MBB EUROPEAN COLLECTION | F60: Equity | G60: Europe | H60: Blend | I60: 45107 | J60: NULL | K60: 0 | L60: EUR | M60: 716863 | N60: Lansdowne European Equity | O60: FALSE | P60: =IF(LEN(A60)>8,"TF","Del") -> Del | Q60: =IF(LEN(M60)>8,"TF","Del") -> Del
...

Sheet Sheet2
A1: MsMap
A2: 708786 | B2: =VLOOKUP(A2,FinalMap!B:B,1,0) -> 708786
A3: 724767 | B3: =VLOOKUP(A3,FinalMap!B:B,1,0) -> 724767
A4: 657375 | B4: =VLOOKUP(A4,FinalMap!B:B,1,0) -> 657375
A5: 719168 | B5: =VLOOKUP(A5,FinalMap!B:B,1,0) -> 719168
A6: 719169 | B6: =VLOOKUP(A6,FinalMap!B:B,1,0) -> 719169
A7: 597012 | B7: =VLOOKUP(A7,FinalMap!B:B,1,0) -> 597012
A8: 597016 | B8: =VLOOKUP(A8,FinalMap!B:B,1,0) -> 597016
A9: 686585 | B9: =VLOOKUP(A9,FinalMap!B:B,1,0) -> 686585
A10: 597009 | B10: =VLOOKUP(A10,FinalMap!B:B,1,0) -> 597009
A11: 724627 | B11: =VLOOKUP(A11,FinalMap!B:B,1,0) -> 724627
A12: 716407 | B12: =VLOOKUP(A12,FinalMap!B:B,1,0) -> 716407
A13: 714548 | B13: =VLOOKUP(A13,FinalMap!B:B,1,0) -> 714548
... A17: 689939 | B17: =VLOOKUP(A17,FinalMap!B:B,1,0) -> 689939
A18: GFJQ | B18: =VLOOKUP(A18,FinalMap!B:B,1,0) -> GFJQ
A19: 722285 | B19: =VLOOKUP(A19,FinalMap!B:B,1,0) -> 722285
A20: 692350 | B20: =VLOOKUP(A20,FinalMap!B:B,1,0) -> 692350
A21: GFJY | B21: =VLOOKUP(A21,FinalMap!B:B,1,0) -> GFJY
A22: 642651 | B22: =VLOOKUP(A22,FinalMap!B:B,1,0) -> 642651
A23: 596990 | B23: =VLOOKUP(A23,FinalMap!B:B,1,0) -> 596990
A24: 681724 | B24: =VLOOKUP(A24,FinalMap!B:B,1,0) -> 681724
A25: 712560 | B25: =VLOOKUP(A25,FinalMap!B:B,1,0) -> 712560
A26: 711342 | B26: =VLOOKUP(A26,FinalMap!B:B,1,0) -> 711342
A27: 718928 | B27: =VLOOKUP(A27,FinalMap!B:B,1,0) -> 718928
A28: 714703 | B28: =VLOOKUP(A28,FinalMap!B:B,1,0) -> 714703
A29: 707638 | B29: =VLOOKUP(A29,FinalMap!B:B,1,0) -> 707638
A30: 722394 | B30: =VLOOKUP(A30,FinalMap!B:B,1,0) -> 722394
A31: 716405 | B31: =VLOOKUP(A31,FinalMap!B:B,1,0) -> 716405
A32: 708787 | B32: =VLOOKUP(A32,FinalMap!B:B,1,0) -> 708787
A33: 714113 | B33: =VLOOKUP(A33,FinalMap!B:B,1,0) -> 714113
... A42: 716863 | B42: =VLOOKUP(A42,FinalMap!B:B,1,0) -> 716863
A43: GFJ9 | B43: =VLOOKUP(A43,FinalMap!B:B,1,0) -> GFJ9
A44: 720798 | B44: =VLOOKUP(A44,FinalMap!B:B,1,0) -> 720798
A45: 714941 | B45: =VLOOKUP(A45,FinalMap!B:B,1,0) -> 714941
A46: 682588 | B46: =VLOOKUP(A46,FinalMap!B:B,1,0) -> #N/A
A47: 688330 | B47: =VLOOKUP(A47,FinalMap!B:B,1,0) -> 688330
A48: 718930 | B48: =VLOOKUP(A48,FinalMap!B:B,1,0) -> 718930
A49: 689206 | B49: =VLOOKUP(A49,FinalMap!B:B,1,0) -> 689206
A50: GFJ8 | B50: =VLOOKUP(A50,FinalMap!B:B,1,0) -> GFJ8
A51: 693779 | B51: =VLOOKUP(A51,FinalMap!B:B,1,0) -> 693779
...

Sheet SAA_Map_Breakdown
A1: Change Date | B1: ID_Code | C1: Weight | D1: SAA | E1: PreMerge_BlendID | F1: Type | G1: IsComposite | H1: Provider | I1: Ticker | J1: Comment | K1: IAR SAA | L1: Currency | M1: Hedged.Status | N1: IAR SAA
A2: 1 | B2: 596990 | C2: 85 | D2: MSCI Germany | E2: MS_RagSAA21 | F2: Del | P2: =IF(K2<>"",N2=D2,"")
A3: 1 | B3: 596990 | C3: 15 | D3: MSCI Germany Small Cap | E3: MS_RagSAA21 | F3: Del | P3: =IF(K3<>"",N3=D3,"")
A4: 1 | B4: 596994 | C4: 80 | D4: MSCI Spain 10/40 | E4: MS_RagSAA70 | F4: Del | P4: =IF(K4<>"",N4=D4,"")
A5: 1 | B5: 596994 | C5: 20 | D5: MSCI Spain Small Cap | E5: MS_RagSAA70 | F5: Del | P5: =IF(K5<>"",N5=D5,"")
A6: 1 | B6: 596998 | C6: 100 | D6: MSCI World | E6: MS_RagSAA76 | F6: Del | P6: =IF(K6<>"",N6=D6,"")
A7: 1 | B7: 597009 | C7: 100 | D7: MSCI USA | E7: MS_RagSAA10 | F7: Del | P7: =IF(K7<>"",N7=D7,"")
A8: 1 | B8: 597012 | C8: 100 | D8: MSCI AC Asia Pacific | E8: MS_RagSAA9 | F8: Del | P8: =IF(K8<>"",N8=D8,"")
A9: 1 | B9: 597016 | C9: 100 | D9: MSCI EM | E9: MS_RagSAA7 | F9: Del | P9: =IF(K9<>"",N9=D9,"")
A10: 1 | B10: 642651 | C10: 100 | D10: DJE GAMAX Junior SAA | E10: MS_RagSAA20 | F10: Del | P10: =IF(K10<>"",N10=D10,"")
A11: 1 | B11: 645766 | C11: 100 | D11: MSCI World Financials | E11: MS_RagSAA69 | F11: Del | P11: =IF(K11<>"",N11=D11,"")
A12: 1 | B12: 657375 | C12: 15 | D12: MSCI World Financial Index local currencies (NDWLFNCL Index) perfectly hedged | E12: MS_RagSAA79 | F12: Del | P12: =IF(K12<>"",N12=D12,"")
A13: 1 | B13: 657375 | C13: 25 | D13: The BofA Merrill Lynch Contingent Capital Index EUR hedged (COCO Index) | E13: MS_RagSAA79 | F13: Del | P13: =IF(K13<>"",N13=D13,"")
... A102: 1 | B102: 724767 | C102: 100 | D102: Refinitiv Global Focus Hgd CB TR USD | E102: MS_RagSAA116 | F102: Del | P102: =IF(K102<>"",N102=D102,"")
A103: 1 | B103: FR0000974149 | C103: 100 | D103: MSCI Europe SMID Growth | E103: MS_RagSAA50 | F103: TF | G103: FALSE | K103: #N/A | L103: #N/A | M103: #N/A | N103: #N/A | P103: =IF(K103<>"",N103=D103,"") -> #N/A
A104: 1 | B104: FR0013429446 | C104: 100 | D104: Refinitiv Global Focus Hgd CB TR USD | E104: MS_RagSAA98 | F104: TF | G104: FALSE | K104: UCBIFX02 Index | L104: USD | M104: Y | N104: FTSE Global Focus Convertible Hedged CB (USD) | P104: =IF(K104<>"",N104=D104,"") -> FALSE
A105: 1 | B105: GFJ9 | C105: 100 | D105: MAN GLG European High Yield - SAA | E105: MS_RagSAA112 | F105: Del | P105: =IF(K105<>"",N105=D105,"")
A106: 1 | B106: GFJQ | C106: 100 | D106: ICE BofA Global Corporate Index (G0BC) | E106: MS_RagSAA81 | F106: Del | P106: =IF(K106<>"",N106=D106,"")
A107: 1 | B107: GFJW | C107: 100 | D107: NB GMB - SAA | E107: MS_RagSAA94 | F107: Del | P107: =IF(K107<>"",N107=D107,"")
A108: 1 | B108: GFJX | C108: 100 | D108: PGIM EM Blend - SAA | E108: MS_RagSAA96 | F108: Del | P108: =IF(K108<>"",N108=D108,"")
A109: 1 | B109: GFJY | C109: 100 | D109: C4 Composite: ICE European Currency High Yield, then 31/03/2022 | E109: MS_RagSAA85 | F109: Del | P109: =IF(K109<>"",N109=D109,"")
A110: 44652 | B110: GFJY | C110: 65 | D110: HPC0 | E110: MS_RagSAA85 | F110: Del | P110: =IF(K110<>"",N110=D110,"")
A111: 44652 | B111: GFJY | C111: 35 | D111: JUC0 | E111: MS_RagSAA85 | F111: Del | P111: =IF(K111<>"",N111=D111,"")
A112: 1 | B112: IE00027GCDQ6 | C112: 70 | D112: ICE BB-B Global High Yield - HW40 | E112: MS_RagSAA101 | F112: TF | G112: TRUE | K112: GBMI Index | L112: EUR | M112: Y | N112: ICE BofAML Global Broad Market | P112: =IF(K112<>"",N112=D112,"") -> FALSE
A113: 1 | B113: IE00027GCDQ6 | C113: 30 | D113: ICE BBB Global Corporate - GBC4 | E113: MS_RagSAA101 | F113: TF | G113: TRUE | K113: GBMI Index | L113: EUR | M113: Y | N113: ICE BofAML Global Broad Market | P113: =IF(K113<>"",N113=D113,"") -> FALSE
A114: 1 | B114: IE0007LWGYY1 | C114: 100 | D114: 50/50 JPM EM Blend (EUR) | E114: MS_RagSAA78 | F114: TF | G114: FALSE | K114: WALD Index | L114: USD | M114: N | N114: ICE BofAML Diversified Emerging Markets Sovereign Bond | P114: =IF(K114<>"",N114=D114,"") -> FALSE
A115: 45809 | B115: IE0007LWGYY1 | C115: 50 | D115: ICE BofAML US Emerging Markets External Sovereign | E115: MS_RagSAA78 | F115: TF | G115: TRUE | H115: ICE | I115: DGOV Index | J115: Changed due to License | K115: WALD Index | L115: USD | M115: N | N115: ICE BofAML Diversified Emerging Markets Sovereign Bond | P115: =IF(K115<>"",N115=D115,"") -> FALSE
A116: 45809 | B116: IE0007LWGYY1 | C116: 50 | D116: ICE BofAML Diversified Emerging Markets Sovereign Bond | E116: MS_RagSAA78 | F116: TF | G116: TRUE | H116: ICE | I116: WALD Index | J116: Changed due to License | K116: WALD Index | L116: USD | M116: N | N116: ICE BofAML Diversified Emerging Markets Sovereign Bond | P116: =IF(K116<>"",N116=D116,"") -> TRUE
A117: 1 | B117: IE00B3DJ5M15 | C117: 100 | D117: MSCI EM | E117: MS_RagSAA37 | F117: TF | G117: FALSE | K117: MXEF Index | L117: EUR | M117: N | N117: MSCI EM | P117: =IF(K117<>"",N117=D117,"") -> TRUE
A118: 1 | B118: IE00B4M6YD48 | C118: 100 | D118: MSCI ACWI Value | E118: MS_RagSAA12 | F118: TF | G118: FALSE | K118: MXWD Index | L118: EUR | M118: N | N118: MSCI AC World | P118: =IF(K118<>"",N118=D118,"") -> FALSE
A119: 1 | B119: IE00B615T757 | C119: 100 | D119: MSCI ACWI Growth | E119: MS_RagSAA11 | F119: TF | G119: FALSE | K119: MXWD Index | L119: USD | M119: N | N119: MSCI AC World | P119: =IF(K119<>"",N119=D119,"") -> FALSE
A120: 1 | B120: IE00BF21WN20 | C120: 100 | D120: MSCI EM Growth | E120: MS_RagSAA62 | F120: TF | G120: FALSE | K120: MXEF Index | L120: EUR | M120: N | N120: MSCI Emerging Markets | P120: =IF(K120<>"",N120=D120,"") -> FALSE
A121: 1 | B121: IE00BFY85J84 | C121: 100 | D121: FTSE Global Core 50/50 | E121: MS_RagSAA31 | F121: TF | G121: FALSE | K121: M8CXRARA Index | L121: EUR | M121: N | N121: MSCI World Core Infrastructure | P121: =IF(K121<>"",N121=D121,"") -> FALSE
A122: 45809 | B122: IE00BFY85J84 | C122: 100 | D122: MSCI World Core Infrastructure | E122: MS_RagSAA31 | F122: TF | G122: FALSE | H122: MSCI | I122: M8CXRARA Index | J122: Changed due to License | K122: M8CXRARA Index | L122: EUR | M122: N | N122: MSCI World Core Infrastructure | P122: =IF(K122<>"",N122=D122,"") -> TRUE
A123: 1 | B123: IE00BKTZQN06 | C123: 50 | D123: FTSE Global Core 50/50 | E123: MS_RagSAA13 | F123: TF | G123: TRUE | K123: M8CXRARA Index | L123: EUR | M123: N | N123: MSCI World Core Infrastructure | P123: =IF(K123<>"",N123=D123,"") -> FALSE
A124: 1 | B124: IE00BKTZQN06 | C124: 50 | D124: S&P Global Infrastructure | E124: MS_RagSAA13 | F124: TF | G124: TRUE | K124: M8CXRARA Index | L124: EUR | M124: N | N124: MSCI World Core Infrastructure | P124: =IF(K124<>"",N124=D124,"") -> FALSE
A125: 45809 | B125: IE00BKTZQN06 | C125: 100 | D125: MSCI World Core Infrastructure | E125: MS_RagSAA13 | F125: TF | G125: FALSE | H125: MSCI | I125: M8CXRARA Index | J125: Changed due to License | K125: M8CXRARA Index | L125: EUR | M125: N | N125: MSCI World Core Infrastructure | P125: =IF(K125<>"",N125=D125,"") -> TRUE
A126: 1 | B126: IE00BM99WQ17 | C126: 100 | D126: JPM EMBI Global Diversified | E126: MS_RagSAA80 | F126: TF | G126: FALSE | K126: DGOV Index | L126: EUR | M126: N | N126: ICE BofAML US Emerging Markets External Sovereign | P126: =IF(K126<>"",N126=D126,"") -> FALSE
A127: 1 | B127: IE00BMWVYP76 | C127: 100 | D127: Refinitiv Global Focus Hgd CB TR USD | E127: MS_RagSAA99 | F127: TF | G127: FALSE | K127: UCBIFX02 Index | L127: USD | M127: Y | N127: FTSE Global Focus Convertible Hedged CB (USD) | P127: =IF(K127<>"",N127=D127,"") -> FALSE
A128: 1 | B128: IE00BNHQBY28 | C128: 100 | D128: FTSE Global Core 50/50 | E128: MS_RagSAA71 | F128: TF | G128: FALSE | K128: M8CXRARA Index | L128: EUR | M128: N | N128: MSCI World Core Infrastructure | P128: =IF(K128<>"",N128=D128,"") -> FALSE
...

Sheet Sheet1
A1: Strategy_Name | B1: Asset_Class | C1: Currency | D1: Managed_Account_ID
A2: DWS German Equity | B2: Equity | C2: EUR | D2: MA10
A3: Wellington Global Consumer | B3: Equity | C3: EUR | D3: MA100
A4: Acadian European Equity | B4: Equity | C4: EUR | D4: MA105
A5: GS All China Equity | B5: Equity | C5: EUR | D5: MA109
A6: MSIM Short Duration Global Bond (CH Int Income) | B6: Fixed Income | C6: EUR | D6: MA11
A7: KBI Circular Economy | B7: Equity | C7: EUR | D7: MA111
A8: Pictet Circular Economy | B8: Equity | C8: EUR | D8: MA112
A9: Eleva European Select Equity Large-Cap | B9: Equity | C9: EUR | D9: MA117
A10: MSIM Global Bond (CH Int Bond) | B10: Fixed Income | C10: EUR | D10: MA12
A11: BlueBay Global IG Credit | B11: Fixed Income | C11: EUR | D11: MA124
A12: Capital Four EUR High Yield | B12: Fixed Income | C12: EUR | D12: MA125
... A80: Zazove Global Convertible | B80: Fixed Income | C80: USD | D80: MA618

Sheet Exceptions
A1: Change Date | B1: ID_Code | C1: Weight | D1: SAA | E1: PreMerge_BlendID | F1: Type | G1: IsComposite | H1: Source | I1: Ticker | J1: Hedged | K1: Currency | L1: Comment
A2: 1 | B2: IE00027GCDQ6 | C2: 0.7 | D2: ICE BB-B Global High Yield - HW40 | E2: MS_RagSAA101 | F2: TF | G2: TRUE | H2: ICE | I2: HW40 Index | J2: FALSE | K2: USD
A3: 1 | B3: IE00027GCDQ6 | C3: 0.3 | D3: ICE BBB Global Corporate - GBC4 | E3: MS_RagSAA101 | F3: TF | G3: TRUE | H3: ICE | I3: GBC4 Index | J3: FALSE | K3: USD
A4: 1 | B4: LU0399027886 | C4: 0.8 | D4: ICE Global Broad Markets EUR Hedged (GBMI) | E4: MS_RagSAA87 | F4: TF | G4: TRUE | H4: ICE | I4: GBMI Index | J4: FALSE | K4: EUR
A5: 1 | B5: LU0399027886 | C5: 0.2 | D5: ICE Global HY Constrained EUR Hedged (HW0C) | E5: MS_RagSAA87 | F5: TF | G5: TRUE | H5: ICE | I5: HW0C Index | J5: FALSE | K5: EUR
A6: 45809 | B6: LU0629658435 | C6: 0.55 | D6: ICE BofAML High Yield US Emerging Markets Liquid Corporate Plus Constrained | E6: MS_RagSAA91 | F6: TF | G6: TRUE | H6: ICE | I6: ECHY Index | J6: FALSE | K6: USD | L6: Changed due to License
A7: 45809 | B7: LU0629658435 | C7: 0.45 | D7: ICE BofAML US Emerging Markets External Sovereign | E7: MS_RagSAA91 | F7: TF | G7: TRUE | H7: ICE | I7: DGOV Index | J7: FALSE | K7: USD | L7: Changed due to License
A8: 1 | B8: LU0853555893 | C8: 0.7 | D8: ICE Global Broad Markets EUR Unhedged (GBMI) | E8: MS_RagSAA89 | F8: TF | G8: TRUE | H8: ICE | I8: GBMI Index | J8: FALSE | K8: EUR
A9: 1 | B9: LU0853555893 | C9: 0.3 | D9: Global HY Constrained EUR Unhedged (HW0C) | E9: MS_RagSAA89 | F9: TF | G9: TRUE | H9: ICE | I9: HW0C Index | J9: FALSE | K9: EUR
A10: 1 | B10: LU1802245560 | C10: 0.5 | D10: MSCI EM IMI | E10: MS_RagSAA60 | F10: TF | G10: TRUE | H10: MSCI | I10: MIMUEMRN Index | J10: FALSE | K10: EUR
A11: 1 | B11: LU1802245560 | C11: 0.5 | D11: MSCI EM IMI Growth | E11: MS_RagSAA60 | F11: TF | G11: TRUE | H11: MSCI | I11: M1EF0008 Index | J11: FALSE | K11: EUR
A12: 1 | B12: LU2200556392 | C12: 0.5 | D12: MSCI China All Shares | E12: MS_RagSAA17 | F12: TF | G12: TRUE | H12: MSCI | I12: MXCNANM Index | J12: FALSE | K12: EUR
A13: 1 | B13: LU2200556392 | C13: 0.5 | D13: MSCI China All Shares Quality | E13: MS_RagSAA17 | F13: TF | G13: TRUE | H13: MSCI | J13: FALSE | K13: EUR
A14: 1 | B14: IE0007LWGYY1 | C14: 0.5 | D14: ICE BofA US Emerging Markets External Sovereign | E14: MS_RagSAA78 | F14: TF | G14: TRUE | H14: ICE | I14: DGOV Index | J14: FALSE | K14: EUR
A15: 1 | B15: IE0007LWGYY1 | C15: 0.5 | D15: ICE BofA Diversified Emerging Markets Sovereign Bond | E15: MS_RagSAA78 | F15: TF | G15: TRUE | H15: ICE | I15: WALD Index | J15: FALSE | K15: EUR
A16: 1 | B16: IE00BKTZQN06 | C16: 1 | D16: MSCI World Core Infrastructure | F16: TF | G16: FALSE | H16: MSCI | I16: M8CXRARA Index | J16: FALSE | K16: EUR | L16: license issues in FS
A17: 1 | B17: IE00BFY85J84 | C17: 1 | D17: MSCI World Core Infrastructure | F17: TF | G17: FALSE | H17: MSCI | I17: M8CXRARA Index | J17: FALSE | K17: EUR | L17: license issues in FS
A18: 1 | B18: IE00BNHQBY28 | C18: 1 | D18: MSCI World Core Infrastructure | F18: TF | G18: FALSE | H18: MSCI | I18: M8CXRARA Index | J18: FALSE | K18: EUR | L18: license issues in FS
